<?xml version='1.0'?>
<robot name="hexabot_v2">
    <link name="j16">
        <inertial>
            <origin xyz="0.014937052515557525 0.008696532029665853 -0.021546297648172005" rpy="-2.4651903288156624e-32 -0.0 3.37788953382074e-47" />
            <mass value="0.34343605071788635" />
            <inertia ixx="0.0001019059928817033" iyy="0.00012898153513847148" izz="0.0001302044711481327" ixy="-2.693305583246607e-05" iyz="-6.311944296618211e-08" ixz="-1.049751123184231e-07" />
        </inertial>
        <visual name="j16_visual">
            <origin xyz="-0.048844357058048134 0.09228235236125475 0.11442487825447276" rpy="-3.1415926535897896 -2.4103671453249196e-16 1.561628666067978" />
            <geometry>
                <mesh filename="meshes/j16.stl" scale="0.001 0.001 0.001" />
            </geometry>
        </visual>
        <collision name="j16_collision">
            <origin xyz="-0.048844357058048134 0.09228235236125475 0.11442487825447276" rpy="-3.1415926535897896 -2.4103671453249196e-16 1.561628666067978" />
            <geometry>
                <mesh filename="meshes/j16.stl" scale="0.001 0.001 0.001" />
            </geometry>
        </collision>
    </link>
    <link name="j15">
        <inertial>
            <origin xyz="0.02143147136178339 -0.0003573967437307024 -0.013368977982688861" rpy="0.0 -5.551115123125714e-17 0.0" />
            <mass value="0.2992908361683288" />
            <inertia ixx="6.256721123435787e-05" iyy="0.00010133343514284046" izz="5.828305900365293e-05" ixy="-1.2043418913027486e-08" iyz="-1.1689616639001408e-06" ixz="-9.639229927390731e-08" />
        </inertial>
        <visual name="j15_visual">
            <origin xyz="0.125462397215982 -0.10658821303962925 0.09656457580547878" rpy="-2.020465079133238 0.48887724122252835 -0.21909131830591536" />
            <geometry>
                <mesh filename="meshes/j15.stl" scale="0.001 0.001 0.001" />
            </geometry>
        </visual>
        <collision name="j15_collision">
            <origin xyz="0.125462397215982 -0.10658821303962925 0.09656457580547878" rpy="-2.020465079133238 0.48887724122252835 -0.21909131830591536" />
            <geometry>
                <mesh filename="meshes/j15.stl" scale="0.001 0.001 0.001" />
            </geometry>
        </collision>
    </link>
    <link name="j14">
        <inertial>
            <origin xyz="-0.026208875153138075 0.012039487945124919 0.0031258480347133143" rpy="5.551115123125783e-17 -0.0 0.0" />
            <mass value="0.3215431541148927" />
            <inertia ixx="8.252579391936436e-05" iyy="0.00013298768788183073" izz="0.00013302279689730498" ixy="-9.697235755220812e-06" iyz="-5.314066104006285e-07" ixz="-6.547517896889746e-06" />
        </inertial>
        <visual name="j14_visual">
            <origin xyz="0.1255961703200813 -0.08112868858823395 -0.13836726978591216" rpy="0.7168392129615309 1.0447073900379367 2.5828734892733167" />
            <geometry>
                <mesh filename="meshes/j14.stl" scale="0.001 0.001 0.001" />
            </geometry>
        </visual>
        <collision name="j14_collision">
            <origin xyz="0.1255961703200813 -0.08112868858823395 -0.13836726978591216" rpy="0.7168392129615309 1.0447073900379367 2.5828734892733167" />
            <geometry>
                <mesh filename="meshes/j14.stl" scale="0.001 0.001 0.001" />
            </geometry>
        </collision>
    </link>
    <link name="j13">
        <inertial>
            <origin xyz="-0.021762564441366372 -0.002096947532456115 0.027782329755323475" rpy="3.469446951953615e-18 -3.762181538524701e-17 -6.93889390390723e-18" />
            <mass value="0.4175018976740224" />
            <inertia ixx="0.0003865781671731537" iyy="0.00044133759741198905" izz="9.773043869787146e-05" ixy="3.578636682807301e-06" iyz="3.7105037550537025e-05" ixz="2.5835735550512883e-06" />
        </inertial>
        <visual name="j13_visual">
            <origin xyz="0.09762997494257025 0.20425095857358794 0.06415567740582333" rpy="2.6647452850953885 -0.23695590700367972 -0.5291026003538094" />
            <geometry>
                <mesh filename="meshes/j13.stl" scale="0.001 0.001 0.001" />
            </geometry>
        </visual>
        <collision name="j13_collision">
            <origin xyz="0.09762997494257025 0.20425095857358794 0.06415567740582333" rpy="2.6647452850953885 -0.23695590700367972 -0.5291026003538094" />
            <geometry>
                <mesh filename="meshes/j13.stl" scale="0.001 0.001 0.001" />
            </geometry>
        </collision>
    </link>
    <link name="base_link">
        <inertial>
            <origin xyz="1.5172351093674352e-07 2.9044790812164575e-05 0.02776127034353392" rpy="0.0 0.0 0.0" />
            <mass value="0.2548577946839391" />
            <inertia ixx="0.0006191396479689932" iyy="0.0006196458527697323" izz="0.0008365930005691299" ixy="2.2762626408731035e-09" iyz="2.017958652895709e-07" ixz="1.0541352820027777e-09" />
        </inertial>
        <visual name="base_link_visual">
            <origin xyz="0.0 0.0 0.0" rpy="0.0 0.0 0.0" />
            <geometry>
                <mesh filename="meshes/base_link.stl" scale="0.001 0.001 0.001" />
            </geometry>
        </visual>
        <collision name="base_link_collision">
            <origin xyz="0.0 0.0 0.0" rpy="0.0 0.0 0.0" />
            <geometry>
                <mesh filename="meshes/base_link.stl" scale="0.001 0.001 0.001" />
            </geometry>
        </collision>
    </link>
    <link name="j1">
        <inertial>
            <origin xyz="-0.021684319364048934 -0.0006048441817562056 0.027861574360801278" rpy="0.0 4.1308102771697725e-17 0.0" />
            <mass value="0.4175018976740224" />
            <inertia ixx="0.0003865127836045069" iyy="0.00044535290202404616" izz="9.378051765403277e-05" ixy="-3.3526013021988483e-06" iyz="-1.1272010420227811e-06" ixz="2.662491624102666e-06" />
        </inertial>
        <visual name="j1_visual">
            <origin xyz="-0.11501101543964203 -0.22257785784977638 0.04109661259075569" rpy="2.56480091992713 -0.2733745014111967 2.7604395096229486" />
            <geometry>
                <mesh filename="meshes/j1.stl" scale="0.001 0.001 0.001" />
            </geometry>
        </visual>
        <collision name="j1_collision">
            <origin xyz="-0.11501101543964203 -0.22257785784977638 0.04109661259075569" rpy="2.56480091992713 -0.2733745014111967 2.7604395096229486" />
            <geometry>
                <mesh filename="meshes/j1.stl" scale="0.001 0.001 0.001" />
            </geometry>
        </collision>
    </link>
    <link name="j2">
        <inertial>
            <origin xyz="0.02877338338534991 0.002050013670186588 0.0030846736560553724" rpy="5.551115123125783e-17 -0.0 0.0" />
            <mass value="0.3215431541148927" />
            <inertia ixx="9.498248188107369e-05" iyy="0.00012122798304210938" izz="0.00013232581377540026" ixy="2.3496336951695936e-05" iyz="-3.769898568047522e-06" ixz="7.248348624951186e-06" />
        </inertial>
        <visual name="j2_visual">
            <origin xyz="-0.16151686285354236 -0.11070782002993941 0.056194714758237105" rpy="-1.039180054375134 -0.8437104774121681 -0.9898881535305697" />
            <geometry>
                <mesh filename="meshes/j2.stl" scale="0.001 0.001 0.001" />
            </geometry>
        </visual>
        <collision name="j2_collision">
            <origin xyz="-0.16151686285354236 -0.11070782002993941 0.056194714758237105" rpy="-1.039180054375134 -0.8437104774121681 -0.9898881535305697" />
            <geometry>
                <mesh filename="meshes/j2.stl" scale="0.001 0.001 0.001" />
            </geometry>
        </collision>
    </link>
    <link name="j4">
        <inertial>
            <origin xyz="-0.014856701557473775 0.008833102279999708 0.02154629764817131" rpy="2.4651903288156624e-32 -0.0 -5.380225868209367e-47" />
            <mass value="0.34343605071788635" />
            <inertia ixx="0.00010240206697651605" iyy="0.00012848546104368257" izz="0.00013020447114817085" ixy="2.717673420566703e-05" iyz="6.407915327870452e-08" ixz="-1.0439205142154999e-07" />
        </inertial>
        <visual name="j4_visual">
            <origin xyz="0.049688303457170103 0.09183069197609019 -0.11442487825447238" rpy="-1.1712852909795443e-14 -2.895351863207672e-15 1.5707963267948943" />
            <geometry>
                <mesh filename="meshes/j4.stl" scale="0.001 0.001 0.001" />
            </geometry>
        </visual>
        <collision name="j4_collision">
            <origin xyz="0.049688303457170103 0.09183069197609019 -0.11442487825447238" rpy="-1.1712852909795443e-14 -2.895351863207672e-15 1.5707963267948943" />
            <geometry>
                <mesh filename="meshes/j4.stl" scale="0.001 0.001 0.001" />
            </geometry>
        </collision>
    </link>
    <link name="j3">
        <inertial>
            <origin xyz="-0.0215531284264647 -0.00023294770026037527 -0.013174733694701892" rpy="0.0 -6.815146932549658e-31 0.0" />
            <mass value="0.2992908361683288" />
            <inertia ixx="6.256861846342536e-05" iyy="0.00010135168136165065" izz="5.826340555587722e-05" ixy="1.2326025150746142e-09" iyz="-7.620692038886296e-07" ixz="5.710474555824173e-08" />
        </inertial>
        <visual name="j3_visual">
            <origin xyz="-0.1245718632132213 0.11085780830161955 0.09283842740964815" rpy="-1.9686594408424947 0.4891166663891411 2.9466353717793847" />
            <geometry>
                <mesh filename="meshes/j3.stl" scale="0.001 0.001 0.001" />
            </geometry>
        </visual>
        <collision name="j3_collision">
            <origin xyz="-0.1245718632132213 0.11085780830161955 0.09283842740964815" rpy="-1.9686594408424947 0.4891166663891411 2.9466353717793847" />
            <geometry>
                <mesh filename="meshes/j3.stl" scale="0.001 0.001 0.001" />
            </geometry>
        </collision>
    </link>
    <link name="j21">
        <inertial>
            <origin xyz="0.012968617190079641 0.0029712908247262314 0.032708247895038046" rpy="0.0 3.935653886122382e-17 0.0" />
            <mass value="0.4175018976740224" />
            <inertia ixx="0.00017556784926371267" iyy="0.0004393328776646163" izz="0.00031074547635434184" ixy="-4.088377861330855e-05" iyz="-2.049431328742491e-05" ixz="-0.00012645577260951552" />
        </inertial>
        <visual name="j21_visual">
            <origin xyz="0.0015861363762448377 -0.215441057792784 0.13431308211124787" rpy="-2.767798471216706 -1.0829966677086935 2.1578208688715037" />
            <geometry>
                <mesh filename="meshes/j21.stl" scale="0.001 0.001 0.001" />
            </geometry>
        </visual>
        <collision name="j21_collision">
            <origin xyz="0.0015861363762448377 -0.215441057792784 0.13431308211124787" rpy="-2.767798471216706 -1.0829966677086935 2.1578208688715037" />
            <geometry>
                <mesh filename="meshes/j21.stl" scale="0.001 0.001 0.001" />
            </geometry>
        </collision>
    </link>
    <link name="j22">
        <inertial>
            <origin xyz="0.016989277800767043 -0.013305480320217972 0.01938952901423754" rpy="5.551115123125783e-17 -0.0 0.0" />
            <mass value="0.3215431541148927" />
            <inertia ixx="0.00012389256037391636" iyy="0.00013421482631985918" izz="9.042889200478524e-05" ixy="-3.2012426226902816e-06" iyz="-5.715290358253766e-06" ixz="-2.0487535096138252e-05" />
        </inertial>
        <visual name="j22_visual">
            <origin xyz="-0.0124544933380316 0.16573558794493493 -0.11780647513995973" rpy="1.6313256796004538 -0.03695138410222945 0.37407457266232197" />
            <geometry>
                <mesh filename="meshes/j22.stl" scale="0.001 0.001 0.001" />
            </geometry>
        </visual>
        <collision name="j22_collision">
            <origin xyz="-0.0124544933380316 0.16573558794493493 -0.11780647513995973" rpy="1.6313256796004538 -0.03695138410222945 0.37407457266232197" />
            <geometry>
                <mesh filename="meshes/j22.stl" scale="0.001 0.001 0.001" />
            </geometry>
        </collision>
    </link>
    <link name="j24">
        <inertial>
            <origin xyz="-0.01507804160104814 -0.008449730315431944 0.021546297648171623" rpy="0.0 1.0947644252537633e-47 -2.846588186495623e-47" />
            <mass value="0.34343605071788635" />
            <inertia ixx="9.842887031281944e-05" iyy="0.00013245865770738222" izz="0.00013020447114814657" ixy="-2.4882808042322662e-05" iyz="-5.836659185696109e-08" ixz="-1.0769020030235628e-07" />
        </inertial>
        <visual name="j24_visual">
            <origin xyz="-0.05468356022341706 0.08894667856268842 -0.11442487825447283" rpy="-8.438100174282935e-15 4.513036243646614e-15 2.61799387799149" />
            <geometry>
                <mesh filename="meshes/j24.stl" scale="0.001 0.001 0.001" />
            </geometry>
        </visual>
        <collision name="j24_collision">
            <origin xyz="-0.05468356022341706 0.08894667856268842 -0.11442487825447283" rpy="-8.438100174282935e-15 4.513036243646614e-15 2.61799387799149" />
            <geometry>
                <mesh filename="meshes/j24.stl" scale="0.001 0.001 0.001" />
            </geometry>
        </collision>
    </link>
    <link name="j23">
        <inertial>
            <origin xyz="0.0006330865388002849 -0.000232947700260433 -0.025252926049672785" rpy="-9.860761315262648e-32 -6.815146932549654e-31 1.9721522630525295e-31" />
            <mass value="0.2992908361683288" />
            <inertia ixx="5.929025462245784e-05" iyy="0.00010135168136157777" izz="6.154176939674759e-05" ixy="6.605875912559459e-07" iyz="-3.799671368537699e-07" ixz="1.8356595005553204e-06" />
        </inertial>
        <visual name="j23_visual">
            <origin xyz="-0.14268637150643806 0.11085780830162018 -0.06146318688855977" rpy="2.990059609186867 1.396929233467656 1.722329371197506" />
            <geometry>
                <mesh filename="meshes/j23.stl" scale="0.001 0.001 0.001" />
            </geometry>
        </visual>
        <collision name="j23_collision">
            <origin xyz="-0.14268637150643806 0.11085780830162018 -0.06146318688855977" rpy="2.990059609186867 1.396929233467656 1.722329371197506" />
            <geometry>
                <mesh filename="meshes/j23.stl" scale="0.001 0.001 0.001" />
            </geometry>
        </collision>
    </link>
    <link name="j5">
        <inertial>
            <origin xyz="-0.013704368244219207 0.0029573170613548206 0.03245471104802595" rpy="0.0 3.783865581974411e-17 6.93889390390723e-18" />
            <mass value="0.4175018976740224" />
            <inertia ixx="0.000165495916597958" iyy="0.00044380330644109564" izz="0.00031634698024381115" ixy="2.073525953235829e-05" iyz="-1.3143742404529438e-05" ixz="0.00012436683731703" />
        </inertial>
        <visual name="j5_visual">
            <origin xyz="-0.0882233854633731 -0.21415374105396567 -0.041482842001383045" rpy="2.133188937120579 0.696607405146892 2.582005724972722" />
            <geometry>
                <mesh filename="meshes/j5.stl" scale="0.001 0.001 0.001" />
            </geometry>
        </visual>
        <collision name="j5_collision">
            <origin xyz="-0.0882233854633731 -0.21415374105396567 -0.041482842001383045" rpy="2.133188937120579 0.696607405146892 2.582005724972722" />
            <geometry>
                <mesh filename="meshes/j5.stl" scale="0.001 0.001 0.001" />
            </geometry>
        </collision>
    </link>
    <link name="j6">
        <inertial>
            <origin xyz="0.013378535501232476 -0.003553806540212062 0.025495304060290557" rpy="5.551115123125784e-17 -0.0 0.0" />
            <mass value="0.3215431541148927" />
            <inertia ixx="0.00012680217151802195" iyy="0.00010810720558780104" izz="0.00011362690159297908" ixy="1.3959726400696466e-05" iyz="2.38034048597524e-05" ixz="-1.1525848317843647e-05" />
        </inertial>
        <visual name="j6_visual">
            <origin xyz="-0.1701850701704577 -0.047002177690467266 -0.10163464936327035" rpy="0.4786488303717364 -0.8077548171344993 -2.615884756160181" />
            <geometry>
                <mesh filename="meshes/j6.stl" scale="0.001 0.001 0.001" />
            </geometry>
        </visual>
        <collision name="j6_collision">
            <origin xyz="-0.1701850701704577 -0.047002177690467266 -0.10163464936327035" rpy="0.4786488303717364 -0.8077548171344993 -2.615884756160181" />
            <geometry>
                <mesh filename="meshes/j6.stl" scale="0.001 0.001 0.001" />
            </geometry>
        </collision>
    </link>
    <link name="j7">
        <inertial>
            <origin xyz="-0.022015271185617954 -0.00023294770026098367 0.011782109280037876" rpy="0.0 5.551115123125714e-17 -1.9721522630525295e-31" />
            <mass value="0.2992908361683288" />
            <inertia ixx="5.938916294305202e-05" iyy="0.00010135168136160032" izz="6.144286107619637e-05" ixy="-6.593549887260643e-07" iyz="-3.8210206704456806e-07" ixz="-1.8927642460159975e-06" />
        </inertial>
        <visual name="j7_visual">
            <origin xyz="0.018285452072863587 0.11085780830161887 0.15400553122327615" rpy="-1.7716556826431693 -0.5410972989853904 2.9407332977415286" />
            <geometry>
                <mesh filename="meshes/j7.stl" scale="0.001 0.001 0.001" />
            </geometry>
        </visual>
        <collision name="j7_collision">
            <origin xyz="0.018285452072863587 0.11085780830161887 0.15400553122327615" rpy="-1.7716556826431693 -0.5410972989853904 2.9407332977415286" />
            <geometry>
                <mesh filename="meshes/j7.stl" scale="0.001 0.001 0.001" />
            </geometry>
        </collision>
    </link>
    <link name="j8">
        <inertial>
            <origin xyz="0.00022133880622055013 -0.01728283247710543 -0.021546297648171384" rpy="-4.930380657631325e-32 -1.0947644252537633e-47 2.533637681713744e-47" />
            <mass value="0.34343605071788635" />
            <inertia ixx="0.0001455003547408476" iyy="8.538717327938243e-05" izz="0.00013020447114820902" ixy="2.2939261633504386e-06" iyz="1.2244574514498974e-07" ixz="-3.2981488943588146e-09" />
        </inertial>
        <visual name="j8_visual">
            <origin xyz="0.10437186244323446 -0.0028840132950753985 0.11442487825447184" rpy="3.141592653589786 1.1137127027565187e-14 -0.523598775598296" />
            <geometry>
                <mesh filename="meshes/j8.stl" scale="0.001 0.001 0.001" />
            </geometry>
        </visual>
        <collision name="j8_collision">
            <origin xyz="0.10437186244323446 -0.0028840132950753985 0.11442487825447184" rpy="3.141592653589786 1.1137127027565187e-14 -0.523598775598296" />
            <geometry>
                <mesh filename="meshes/j8.stl" scale="0.001 0.001 0.001" />
            </geometry>
        </collision>
    </link>
    <link name="j12">
        <inertial>
            <origin xyz="0.015078039126340414 0.00844973007877897 0.02154629764817158" rpy="0.0 -0.0 -4.3790577010150533e-47" />
            <mass value="0.34343605071788635" />
            <inertia ixx="9.842887031279515e-05" iyy="0.00013245865770736205" izz="0.00013020447114818473" ixy="-2.4882808042328734e-05" iyz="5.836659184221478e-08" ixz="1.0769020031275999e-07" />
        </inertial>
        <visual name="j12_visual">
            <origin xyz="0.054683557748710296 -0.08894667879934161 -0.11442487825447216" rpy="-2.6645352591003836e-15 -9.853229343548114e-15 -0.5235987755983129" />
            <geometry>
                <mesh filename="meshes/j12.stl" scale="0.001 0.001 0.001" />
            </geometry>
        </visual>
        <collision name="j12_collision">
            <origin xyz="0.054683557748710296 -0.08894667879934161 -0.11442487825447216" rpy="-2.6645352591003836e-15 -9.853229343548114e-15 -0.5235987755983129" />
            <geometry>
                <mesh filename="meshes/j12.stl" scale="0.001 0.001 0.001" />
            </geometry>
        </collision>
    </link>
    <link name="j11">
        <inertial>
            <origin xyz="-0.022133085110469217 -0.00023294770026119682 -0.011986168345959313" rpy="9.860761315262645e-32 -7.682620950555758e-31 0.0" />
            <mass value="0.2992908361683288" />
            <inertia ixx="5.929025462247398e-05" iyy="0.00010135168136160555" izz="6.154176939677177e-05" ixy="-6.605875912802296e-07" iyz="3.799671368383782e-07" ixz="1.83565950057091e-06" />
        </inertial>
        <visual name="j11_visual">
            <origin xyz="0.12118637293476817 0.11085780830161984 0.024224092492927733" rpy="-0.15153304440286708 -1.3969292334676677 1.4192632823922275" />
            <geometry>
                <mesh filename="meshes/j11.stl" scale="0.001 0.001 0.001" />
            </geometry>
        </visual>
        <collision name="j11_collision">
            <origin xyz="0.12118637293476817 0.11085780830161984 0.024224092492927733" rpy="-0.15153304440286708 -1.3969292334676677 1.4192632823922275" />
            <geometry>
                <mesh filename="meshes/j11.stl" scale="0.001 0.001 0.001" />
            </geometry>
        </collision>
    </link>
    <link name="j10">
        <inertial>
            <origin xyz="-0.013612666705773222 0.002161612977258356 0.025153213643663914" rpy="5.551115123125783e-17 -5.551115123125783e-17 -2.7755575615628914e-17" />
            <mass value="0.3215431541148927" />
            <inertia ixx="0.00011675587246444729" iyy="0.00011991248468364303" izz="0.00011186792155078791" ixy="-1.5515561647743446e-05" iyz="1.8806697365587097e-05" ixz="1.9383693743750313e-05" />
        </inertial>
        <visual name="j10_visual">
            <origin xyz="-0.029603156710166445 -0.038260530188153626 -0.1981307712536259" rpy="0.9074991904924701 0.08580280667568446 3.0888587683735733" />
            <geometry>
                <mesh filename="meshes/j10.stl" scale="0.001 0.001 0.001" />
            </geometry>
        </visual>
        <collision name="j10_collision">
            <origin xyz="-0.029603156710166445 -0.038260530188153626 -0.1981307712536259" rpy="0.9074991904924701 0.08580280667568446 3.0888587683735733" />
            <geometry>
                <mesh filename="meshes/j10.stl" scale="0.001 0.001 0.001" />
            </geometry>
        </collision>
    </link>
    <link name="j9">
        <inertial>
            <origin xyz="-0.03507815001034433 0.0003247189663730721 0.004391162151775099" rpy="0.0 3.8706017557732514e-17 6.93889390390723e-18" />
            <mass value="0.4175018976740224" />
            <inertia ixx="0.00016896795547428965" iyy="0.00044553262944404154" izz="0.0003111456183644472" ixy="5.490849116800255e-07" iyz="1.288685637433046e-06" ixz="-0.000127867723385095" />
        </inertial>
        <visual name="j9_visual">
            <origin xyz="0.00790840532081309 -0.21447763101266057 -0.09645110943332377" rpy="0.3733718984006412 1.0871896291067016 1.1299259569232751" />
            <geometry>
                <mesh filename="meshes/j9.stl" scale="0.001 0.001 0.001" />
            </geometry>
        </visual>
        <collision name="j9_collision">
            <origin xyz="0.00790840532081309 -0.21447763101266057 -0.09645110943332377" rpy="0.3733718984006412 1.0871896291067016 1.1299259569232751" />
            <geometry>
                <mesh filename="meshes/j9.stl" scale="0.001 0.001 0.001" />
            </geometry>
        </collision>
    </link>
    <link name="j20">
        <inertial>
            <origin xyz="7.39001562512276e-05 0.01728409098491511 -0.021204414439682774" rpy="4.930380657631325e-32 -0.0 6.224477720316364e-47" />
            <mass value="0.34343601261254497" />
            <inertia ixx="0.00014556114062787284" iyy="8.53263294589669e-05" izz="0.00013020446649093792" ixy="1.2659401709947356e-06" iyz="-1.224749385789018e-07" ixz="1.2064590951818395e-09" />
        </inertial>
        <visual name="j20_visual">
            <origin xyz="0.11722637864859917 0.21183045899545647 0.11464234656930597" rpy="-2.932291948299226 0.15525247705927828 -0.436332312998582" />
            <geometry>
                <mesh filename="meshes/j20.stl" scale="0.001 0.001 0.001" />
            </geometry>
        </visual>
        <collision name="j20_collision">
            <origin xyz="0.11722637864859917 0.21183045899545647 0.11464234656930597" rpy="-2.932291948299226 0.15525247705927828 -0.436332312998582" />
            <geometry>
                <mesh filename="meshes/j20.stl" scale="0.001 0.001 0.001" />
            </geometry>
        </collision>
    </link>
    <link name="j19">
        <inertial>
            <origin xyz="0.021369029307827105 0.001102926410091043 0.013428078694660126" rpy="6.938893903907228e-18 -8.673617379884035e-19 0.0" />
            <mass value="0.29929081715461486" />
            <inertia ixx="5.93830278586605e-05" iyy="0.00010108747860429345" izz="6.171316879765283e-05" ixy="-3.1200014453955617e-06" iyz="1.46917340112728e-06" ixz="1.6522194722889688e-06" />
        </inertial>
        <visual name="j19_visual">
            <origin xyz="0.15533943751737816 -0.10950680461812975 -0.17487758541218562" rpy="1.457690191126277 0.6800170843560119 -3.0820519723242725" />
            <geometry>
                <mesh filename="meshes/j19.stl" scale="0.001 0.001 0.001" />
            </geometry>
        </visual>
        <collision name="j19_collision">
            <origin xyz="0.15533943751737816 -0.10950680461812975 -0.17487758541218562" rpy="1.457690191126277 0.6800170843560119 -3.0820519723242725" />
            <geometry>
                <mesh filename="meshes/j19.stl" scale="0.001 0.001 0.001" />
            </geometry>
        </collision>
    </link>
    <link name="j18">
        <inertial>
            <origin xyz="-0.011708587645868197 -0.009003571659530562 0.02458670486497873" rpy="0.0 -3.469446951953614e-18 6.938893903907228e-18" />
            <mass value="0.32154320272135206" />
            <inertia ixx="0.00012345781032943343" iyy="0.00012910896643683118" izz="9.596961790836421e-05" ixy="8.014072466591782e-06" iyz="-1.5213192000938631e-05" ixz="1.9406783029250127e-05" />
        </inertial>
        <visual name="j18_visual">
            <origin xyz="-0.17130307030018174 0.12006489248623735 0.10596391970664876" rpy="-1.7182546840971984 0.8747971094317829 3.097104533201569" />
            <geometry>
                <mesh filename="meshes/j18.stl" scale="0.001 0.001 0.001" />
            </geometry>
        </visual>
        <collision name="j18_collision">
            <origin xyz="-0.17130307030018174 0.12006489248623735 0.10596391970664876" rpy="-1.7182546840971984 0.8747971094317829 3.097104533201569" />
            <geometry>
                <mesh filename="meshes/j18.stl" scale="0.001 0.001 0.001" />
            </geometry>
        </collision>
    </link>
    <link name="j17">
        <inertial>
            <origin xyz="0.015916016662758638 0.0027718225923391506 -0.03144609035500171" rpy="-2.1684043449710093e-19 -1.0875903042745218e-18 4.336808689942019e-19" />
            <mass value="0.4175004627535813" />
            <inertia ixx="0.0001489341226400022" iyy="0.0004441094765834169" izz="0.00033259879092206333" ixy="-1.9512885842370556e-05" iyz="1.0697431876515892e-05" ixz="0.00011299509174935403" />
        </inertial>
        <visual name="j17_visual">
            <origin xyz="-0.22761973094411694 -0.14522821058528973 -0.06265190834715029" rpy="2.114937524706365 0.8932829258825732 2.2421834096665734" />
            <geometry>
                <mesh filename="meshes/j17.stl" scale="0.001 0.001 0.001" />
            </geometry>
        </visual>
        <collision name="j17_collision">
            <origin xyz="-0.22761973094411694 -0.14522821058528973 -0.06265190834715029" rpy="2.114937524706365 0.8932829258825732 2.2421834096665734" />
            <geometry>
                <mesh filename="meshes/j17.stl" scale="0.001 0.001 0.001" />
            </geometry>
        </collision>
    </link>
    <joint name="j14_Revolute-13" type="continuous">
        <origin xyz="-0.05871964956777625 0.009476148417755575 -0.02376352474655704" rpy="-1.5707963267949376 1.2396250505619195 1.388321618431692" />
        <parent link="j14" />
        <child link="j13" />
        <axis xyz="0.9978723294817885 -0.06517277091228285 0.0016010497194174447" />
    </joint>
    <joint name="j15_Revolute-14" type="continuous">
        <origin xyz="0.02110790236030496 -0.001157940000000055 -0.04286760067074699" rpy="-1.570796326794842 -1.366655656255058 1.2040533058673561" />
        <parent link="j15" />
        <child link="j14" />
        <axis xyz="-0.9846334859571977 0.17462864248371585 -0.0011725259365251619" />
    </joint>
    <joint name="j16_Revolute-15" type="continuous">
        <origin xyz="0.055488470000000005 0.007928719999999955 -0.021500000000000005" rpy="-1.570796326794896 1.2623264758054082e-15 2.0943951023932272" />
        <parent link="j16" />
        <child link="j15" />
        <axis xyz="-0.9999583338488297 1.0921756444988922e-15 0.009167360321936713" />
    </joint>
    <joint name="base_link_Revolute-16" type="continuous">
        <origin xyz="0.03499999988167243 0.06062178123735415 0.011500003091019907" rpy="3.141592653589793 3.8302694349568106e-15 1.5707963267948994" />
        <parent link="base_link" />
        <child link="j16" />
        <axis xyz="-4.930380657631324e-32 2.030610284917227e-16 0.9999999999999999" />
    </joint>
    <joint name="base_link_Revolute-26" type="continuous">
        <origin xyz="-0.03500000011832597 -0.06062177876264647 0.011500003091020351" rpy="-5.361279358792549e-16 3.8302694349568106e-15 1.5707963267948994" />
        <parent link="base_link" />
        <child link="j4" />
        <axis xyz="4.930380657631324e-32 -2.0306102849172278e-16 0.9999999999999999" />
    </joint>
    <joint name="j4_Revolute-27" type="continuous">
        <origin xyz="-0.05541345000000001 0.008437079999999994 0.021500000000000005" rpy="-1.5707963267948961 -9.106144574205576e-16 -2.0943951023932272" />
        <parent link="j4" />
        <child link="j3" />
        <axis xyz="-0.9999996503124184 -1.0864699600460301e-15 2.0189218741251125e-07" />
    </joint>
    <joint name="j3_Revolute-28" type="continuous">
        <origin xyz="-0.02149999700055961 -0.0007545600000000485 -0.042681332832450646" rpy="1.5707963267949516 1.366655656255058 -1.2040533058673557" />
        <parent link="j3" />
        <child link="j2" />
        <axis xyz="0.9824276109832222 -0.18653619939040444 0.0063383479537031185" />
    </joint>
    <joint name="base_link_Revolute-30" type="continuous">
        <origin xyz="0.03499999988167279 -0.0606217787626463 0.011500003091020368" rpy="-9.104235831017343e-16 3.8302694349568106e-15 1.5707963267948994" />
        <parent link="base_link" />
        <child link="j24" />
        <axis xyz="4.930380657631324e-32 -5.773566757142021e-16 0.9999999999999999" />
    </joint>
    <joint name="j24_Revolute-31" type="continuous">
        <origin xyz="-0.035013450000000015 -0.04377091999999998 0.021499999999999974" rpy="-1.5707963267948963 -5.864649183999587e-16 -2.0943951023932272" />
        <parent link="j24" />
        <child link="j23" />
        <axis xyz="-0.49999965031239085 -1.0864699600460287e-15 -0.8660252018922353" />
    </joint>
    <joint name="j23_Revolute-32" type="continuous">
        <origin xyz="0.026213119046747196 -0.0007545599999999953 -0.03996021401381455" rpy="-1.570796326794842 1.366655656255058 -1.2040533058673557" />
        <parent link="j23" />
        <child link="j22" />
        <axis xyz="-0.5558301879838772 0.218852047974407 -0.8019703999420525" />
    </joint>
    <joint name="base_link_Revolute-34" type="continuous">
        <origin xyz="-0.07000000011832555 1.2373536795173835e-09 0.011500003091020101" rpy="-3.141592653589793 3.8302694349568106e-15 1.5707963267948994" />
        <parent link="base_link" />
        <child link="j8" />
        <axis xyz="-4.930380657631324e-32 3.7429564722247916e-16 0.9999999999999999" />
    </joint>
    <joint name="j8_Revolute-35" type="continuous">
        <origin xyz="-0.02040000000000001 -0.052208000000000025 -0.02149999999999998" rpy="1.5707963267948974 1.4106200056335825e-15 2.0943951023932272" />
        <parent link="j8" />
        <child link="j7" />
        <axis xyz="-0.5000000000000275 6.964140557187773e-32 0.8660254037844226" />
    </joint>
    <joint name="j7_Revolute-36" type="continuous">
        <origin xyz="-0.047542171047306805 -0.000754560000000053 -0.0030172042439359447" rpy="1.5707963267949505 1.366655656255058 -1.2040533058673555" />
        <parent link="j7" />
        <child link="j6" />
        <axis xyz="0.4299425091622117 -0.38923032307281025 0.8146469540407901" />
    </joint>
    <joint name="j6_Revolute-37" type="continuous">
        <origin xyz="0.004862343695578062 -0.03279747739369628 0.054801306485259556" rpy="1.5707963267948555 1.2396250505619197 1.3883216184316927" />
        <parent link="j6" />
        <child link="j5" />
        <axis xyz="0.49301452528697876 0.021658502338377413 0.8697511069078979" />
    </joint>
    <joint name="base_link_Revolute-38" type="continuous">
        <origin xyz="-0.035000000118326324 0.06062178123735398 0.011500003091019879" rpy="-3.330669073875321e-16 3.8302694349568106e-15 1.5707963267948994" />
        <parent link="base_link" />
        <child link="j12" />
        <axis xyz="4.930380657631324e-32 0.0 0.9999999999999999" />
    </joint>
    <joint name="j12_Revolute-39" type="continuous">
        <origin xyz="0.056663450000000004 0.006272020000000005 0.0215" rpy="-1.570796326794896 -1.1535462635566335e-15 -2.0943951023932272" />
        <parent link="j12" />
        <child link="j11" />
        <axis xyz="0.49999965031239085 1.153545725715584e-15 0.8660252018922352" />
    </joint>
    <joint name="j11_Revolute-40" type="continuous">
        <origin xyz="-0.047713117000561064 -0.0007545600000000574 0.0027211228324484082" rpy="1.5707963267949514 1.366655656255058 -1.2040533058673553" />
        <parent link="j11" />
        <child link="j10" />
        <axis xyz="-0.5491400156581436 -0.1865361993904045 0.8146468122321214" />
    </joint>
    <joint name="j10_Revolute-41" type="continuous">
        <origin xyz="-0.051839659547718214 -0.013164433361545642 0.03465947305230104" rpy="1.5707963267948557 1.2396250505619195 1.388321618431692" />
        <parent link="j10" />
        <child link="j9" />
        <axis xyz="-0.5060939807576602 -0.01382568950063379 0.8623676743876113" />
    </joint>
    <joint name="j22_Revolute-42" type="continuous">
        <origin xyz="0.013011348357550143 -0.012301301377680965 0.06181741397156983" rpy="-1.5707963267949374 -1.2396250505619197 -1.3883216184316922" />
        <parent link="j22" />
        <child link="j21" />
        <axis xyz="0.5045501804570361 0.05711130797468446 -0.8614915477125665" />
    </joint>
    <joint name="j2_Revolute-43" type="continuous">
        <origin xyz="0.058462901285520445 -0.011887468711753174 -0.02414098793285149" rpy="1.5707963267948557 1.2396250505619197 1.388321618431692" />
        <parent link="j2" />
        <child link="j1" />
        <axis xyz="0.9983366058943269 0.05712700107603655 0.007821495857809033" />
    </joint>
    <joint name="base_link_Revolute-44" type="continuous">
        <origin xyz="0.069999999881672 1.2373540103638449e-09 0.011500003091020146" rpy="3.1415926535897927 3.8302694349568106e-15 1.5707963267948994" />
        <parent link="base_link" />
        <child link="j20" />
        <axis xyz="-4.930380657631324e-32 -3.7429564722247936e-16 0.9999999999999999" />
    </joint>
    <joint name="j20_Revolute-45" type="continuous">
        <origin xyz="0.02128879000000001 0.051851929999999984 -0.021158109999999977" rpy="-1.624737815509986 -0.11244028686400741 2.0193022710086654" />
        <parent link="j20" />
        <child link="j19" />
        <axis xyz="0.44611304708161076 0.0021238143697224128 0.8949739775619645" />
    </joint>
    <joint name="j19_Revolute-46" type="continuous">
        <origin xyz="0.04766977683543601 0.003470336825515834 0.00025309338691887007" rpy="-2.293947733612524 -1.5470883084001512 -0.8102688538055876" />
        <parent link="j19" />
        <child link="j18" />
        <axis xyz="-0.4315053515154379 -0.039048613650013136 0.901265054088724" />
    </joint>
    <joint name="j18_Revolute-47" type="continuous">
        <origin xyz="-0.006497530073410172 0.008115118706654828 0.06287972250774984" rpy="-1.5707963267950495 -1.4972843376518894 -1.5370641140837185" />
        <parent link="j18" />
        <child link="j17" />
        <axis xyz="0.43203951219381476 -0.02160212212619022 0.9015960946327217" />
    </joint>
</robot>